<?xml version="1.0"?>
<robot name="mecanum_bot">
  <!-- Base Link -->
  <link name="base_link">
    <visual>
      <geometry>
        <box size="0.4 0.4 0.1"/> <!-- Chassis dimensions -->
      </geometry>
      <material name="blue">
        <color rgba="0 0 1 1"/>
      </material>
    </visual>
  </link>

  <!-- Front Left Wheel -->
  <link name="front_left_wheel">
    <visual>
      <geometry>
        <cylinder length="0.05" radius="0.05"/> <!-- Wheel dimensions -->
      </geometry>
      <material name="black">
        <color rgba="0 0 0 1"/>
      </material>
    </visual>
  </link>
  <joint name="front_left_wheel_joint" type="continuous">
    <parent link="base_link"/>
    <child link="front_left_wheel"/>
    <!-- Position wheel at front-left corner -->
    <origin xyz="0.2 0.2 -0.05" rpy="0 1.5708 0"/> <!-- Rotate cylinder to face forward -->
  </joint>

  <!-- Front Right Wheel -->
  <link name="front_right_wheel">
    <visual>
      <geometry>
        <cylinder length="0.05" radius="0.05"/>
      </geometry>
      <material name="black">
        <color rgba="0 0 0 1"/>
      </material>
    </visual>
  </link>
  <joint name="front_right_wheel_joint" type="continuous">
    <parent link="base_link"/>
    <child link="front_right_wheel"/>
    <!-- Position wheel at front-right corner -->
    <origin xyz="0.2 -0.2 -0.05" rpy="0 1.5708 0"/>
  </joint>

  <!-- Back Left Wheel -->
  <link name="back_left_wheel">
    <visual>
      <geometry>
        <cylinder length="0.05" radius="0.05"/>
      </geometry>
      <material name="black">
        <color rgba="0 0 0 1"/>
      </material>
    </visual>
  </link>
  <joint name="back_left_wheel_joint" type="continuous">
    <parent link="base_link"/>
    <child link="back_left_wheel"/>
    <!-- Position wheel at back-left corner -->
    <origin xyz="-0.2 0.2 -0.05" rpy="0 1.5708 0"/>
  </joint>

  <!-- Back Right Wheel -->
  <link name="back_right_wheel">
    <visual>
      <geometry>
        <cylinder length="0.05" radius="0.05"/>
      </geometry>
      <material name="black">
        <color rgba="0 0 0 1"/>
      </material>
    </visual>
  </link>
  <joint name="back_right_wheel_joint" type="continuous">
    <parent link="base_link"/>
    <child link="back_right_wheel"/>
    <!-- Position wheel at back-right corner -->
    <origin xyz="-0.2 -0.2 -0.05" rpy="0 1.5708 0"/>
  </joint>

</robot>
